<?xml version="1.0"?>
<!-- Revolute-Revolute Manipulator -->
<robot name="robotis_manipulator_h" xmlns:xacro="http://www.ros.org/wiki/xacro">
    
    <!--     <xacro:property name="pi" value="3.141592654" /> -->
    
    <!-- Import all Gazebo-customization elements, including Gazebo colors -->
    <xacro:include filename="$(find my_robotic_arm)/urdf/manipulator_h.gazebo" />
    <!-- Import Rviz colors -->
    <xacro:include filename="$(find my_robotic_arm)/urdf/materials.xacro" />
    <!--         IMPORT XTION_pro_live -->
    <!--     <xacro:include filename="$(find my_robotic_arm)/urdf/xtion_pro_live.urdf.xacro"/> -->
    
    
    <!-- Constants -->
    <xacro:property name="deg_to_rad" value="0.01745329251994329577"/>
    <xacro:property name="pi" value="3.141592654" />
    <xacro:property name="M_SCALE" value="0.001 0.001 0.001"/> 
    <xacro:property name="M_PI" value="3.14159"/>
    
    
    <xacro:macro name="inertial_matrix" params="mass">
        <inertial>
            <mass value="${mass}" />
            <inertia ixx="1.0" ixy="0.0" ixz="0.0" iyy="0.5" iyz="0.0" izz="1.0" />
        </inertial>
    </xacro:macro>
    
    <!--    <xacro:macro name="transmission_block" params="joint_name">
    <transmission name="tran1">
    <type>transmission_interface/SimpleTransmission</type>
    <joint name="${joint_name}">
    <hardwareInterface>PositionJointInterface</hardwareInterface>
    </joint>
    <actuator name="motor1">
    <hardwareInterface>PositionJointInterface</hardwareInterface>
    <mechanicalReduction>1</mechanicalReduction>
    </actuator>
    </transmission>
    </xacro:macro>-->
    
    
    
    
    
    
    
    
    
    
    
    
    
    
    <!-- Used for fixing robot to Gazebo 'link 1' -->
    <link name="world">
    </link>
    
    <joint name="world_fixed" type="fixed">
        <origin xyz="0 0 0" rpy="0 0 0"/>
        <parent link="world"/>
        <child link="link1"/>
    </joint>
    
    <!-- link 1 -->
    <link name="link1">
        <collision>
            <origin xyz="0 0 0" rpy="0 0 0"/>
            <geometry>
                <mesh filename="package://my_robotic_arm/meshes/link_1.stl" scale="0.001 0.001 0.001"/>
            </geometry>
        </collision>
        
        <visual>
            <origin xyz="0 0 0" rpy="0 0 0"/>
            <geometry>
                <mesh filename="package://my_robotic_arm/meshes/link_1.stl" scale="0.001 0.001 0.001"/>
            </geometry>
            <material name="grey"/>
        </visual>
        
        <inertial>
            <origin xyz="0.00023 0.00000 0.06223" rpy="0 0 0"/>
            <!--<origin xyz="0.00023 0.00000 -0.06377" rpy="0 0 0"/>-->
            <mass value="0.85644"/>
            <inertia ixx="1.0" ixy="0.0" ixz="0.0" iyy="1.0" iyz="0.0" izz="1.0" />
            <!--<inertia ixx="0.00121064" ixy="0.0" ixz="0.00001100" iyy="0.00120886" iyz="0.0" izz="0.00038103" />-->
        </inertial>
    </link>
    
    <!-- Joint 1 -->
    <joint name="joint1" type="revolute">
        <parent link="link1"/>
        <child link="link2"/>
        <origin xyz="0.0 0.0 0.126" rpy="0 0 0"/>
        <axis xyz="0 0 1"/>
        <limit velocity="6.5" effort="1000" lower="${-pi*0.5}" upper="${pi*0.5}" />
        <dynamics damping="0.7"/>
    </joint>
    
    <transmission name="tran1">
        <type>transmission_interface/SimpleTransmission</type>
        <joint name="joint1">
            <hardwareInterface>EffortJointInterface</hardwareInterface>
        </joint>
        <actuator name="motor1">
            <hardwareInterface>EffortJointInterface</hardwareInterface>
            <mechanicalReduction>1</mechanicalReduction>
        </actuator>
    </transmission>
    
    <!-- link 2 -->
    <link name="link2">
        <collision>
            <origin xyz="0 0 0" rpy="0 0 0"/>
            <geometry>
                <mesh filename="package://my_robotic_arm/meshes/link_2.stl" scale="0.001 0.001 0.001"/>
            </geometry>
        </collision>
        
        <visual>
            <origin xyz="0 0 0" rpy="0 0 0"/>
            <geometry>
                <mesh filename="package://my_robotic_arm/meshes/link_2.stl" scale="0.001 0.001 0.001"/>
            </geometry>
            <material name="grey"/>
        </visual>
        
        <inertial>
            <origin xyz="0.00000 0.00080 0.03183" rpy="0 0 0"/>
            <!--<origin xyz="0.00000 -0.06820 -0.00117" rpy="0 0 0"/>-->
            <mass value="0.94658"/>
            <inertia ixx="1.0" ixy="0.0" ixz="0.0" iyy="1.0" iyz="0.0" izz="1.0" />
            <!--<inertia ixx="0.00152547" ixy="0.0" ixz="0.0" iyy="0.00045954" iyz="-0.00001086" izz="0.00151740" />-->
        </inertial>
    </link>
    
    <!-- Joint 2 -->
    <joint name="joint2" type="revolute">
        <parent link="link2"/>
        <child link="link3"/>
        <origin xyz="0.0 0.069 0.033" rpy="0 0 0"/>
        <axis xyz="0 1 0"/>
        <limit velocity="6.5" effort="1000" lower="${-pi*0.5}" upper="${pi*0.5}" />
        <dynamics damping="0.7"/>
    </joint>
    
    <transmission name="tran2">
        <type>transmission_interface/SimpleTransmission</type>
        <joint name="joint2">
            <hardwareInterface>EffortJointInterface</hardwareInterface>
        </joint>
        <actuator name="motor2">
            <hardwareInterface>EffortJointInterface</hardwareInterface>
            <mechanicalReduction>1</mechanicalReduction>
        </actuator>
    </transmission>
    
    <!-- link 3 -->
    <link name="link3">
        <collision>
            <origin xyz="0 0 0" rpy="0 0 0"/>
            <geometry>
                <mesh filename="package://my_robotic_arm/meshes/link_3.stl" scale="0.001 0.001 0.001"/>
            </geometry>
        </collision>
        
        <visual>
            <origin xyz="0 0 0" rpy="0 0 0"/>
            <geometry>
                <mesh filename="package://my_robotic_arm/meshes/link_3.stl" scale="0.001 0.001 0.001"/>
            </geometry>
            <material name="grey"/>
        </visual>
        
        <inertial>
            <origin xyz="0.01768 -0.06881 0.20524" rpy="0 0 0"/>
            <!--<origin xyz="-0.01232 -0.05731 -0.05876" rpy="0 0 0"/>-->
            <mass value="1.30260"/>
            <inertia ixx="1.0" ixy="0.0" ixz="0.0" iyy="1.0" iyz="0.0" izz="1.0" />
            <!--<inertia ixx="0.01111021" ixy="0.00001331" ixz="-0.00134208" iyy="0.01046642" iyz="0.00016235" izz="0.00202081" />-->
        </inertial>
    </link>
    
    <!-- Joint 3 -->
    <joint name="joint3" type="revolute">
        <parent link="link3"/>
        <child link="link4"/>
        <origin xyz="0.03000 -0.01150 0.26400" rpy="0 0 0"/>
        <axis xyz="0 1 0"/>
        <limit velocity="6.5" effort="1000" lower="${-pi*0.5}" upper="${pi*0.5}" />
        <dynamics damping="0.7"/>
    </joint>
    
    <transmission name="tran3">
        <type>transmission_interface/SimpleTransmission</type>
        <joint name="joint3">
            <hardwareInterface>EffortJointInterface</hardwareInterface>
        </joint>
        <actuator name="motor3">
            <hardwareInterface>EffortJointInterface</hardwareInterface>
            <mechanicalReduction>1</mechanicalReduction>
        </actuator>
    </transmission>
    
    <!-- link 4 -->
    <link name="link4">
        <collision>
            <origin xyz="0 0 0" rpy="0 0 0"/>
            <geometry>
                <mesh filename="package://my_robotic_arm/meshes/link_4.stl" scale="0.001 0.001 0.001"/>
            </geometry>
        </collision>
        
        <visual>
            <origin xyz="0 0 0" rpy="0 0 0"/>
            <geometry>
                <mesh filename="package://my_robotic_arm/meshes/link_4.stl" scale="0.001 0.001 0.001"/>
            </geometry>
            <material name="grey"/>
        </visual>
        
        <inertial>
            <origin xyz="0.12475 -0.05716 0.02979" rpy="0 0 0"/>
            <!--<origin xyz="-0.07025 0.00034 -0.00021" rpy="0 0 0"/>-->
            <mass value="1.15977"/>
            <inertia ixx="1.0" ixy="0.0" ixz="0.0" iyy="1.0" iyz="0.0" izz="1.0" />
            <!--<inertia ixx="0.00096726" ixy="0.00004383" ixz="-0.00002771" iyy="0.00318801" iyz="0.00000627" izz="0.00341484" />-->
        </inertial>
    </link>
    
    <!-- Joint 4 -->
    <joint name="joint4" type="revolute">
        <parent link="link4"/>
        <child link="link5"/>
        <origin xyz="0.19500 -0.05750 0.03000" rpy="0 0 0"/>
        <axis xyz="1 0 0"/>
        <limit velocity="6.5" effort="1000" lower="${-pi*0.5}" upper="${pi*0.5}" />
        <dynamics damping="0.7"/>
    </joint>
    
    <transmission name="tran4">
        <type>transmission_interface/SimpleTransmission</type>
        <joint name="joint4">
            <hardwareInterface>EffortJointInterface</hardwareInterface>
        </joint>
        <actuator name="motor4">
            <hardwareInterface>EffortJointInterface</hardwareInterface>
            <mechanicalReduction>1</mechanicalReduction>
        </actuator>
    </transmission>
    
    <!-- link 5 -->
    <link name="link5">
        <collision>
            <origin xyz="0 0 0" rpy="0 0 0"/>
            <geometry>
                <mesh filename="package://my_robotic_arm/meshes/link_5.stl" scale="0.001 0.001 0.001"/>
            </geometry>
        </collision>
        
        <visual>
            <origin xyz="0 0 0" rpy="0 0 0"/>
            <geometry>
                <mesh filename="package://my_robotic_arm/meshes/link_5.stl" scale="0.001 0.001 0.001"/>
            </geometry>
            <material name="grey"/>
        </visual>
        
        <inertial>
            <origin xyz="0.05642 -0.00217 0.00002" rpy="0 0 0"/>
            <!--<origin xyz="-0.00658 -0.04717 0.00002" rpy="0 0 0"/>-->
            <mass value="0.44688"/>
            <inertia ixx="1.0" ixy="0.0" ixz="0.0" iyy="1.0" iyz="0.0" izz="1.0" />
            <!--<inertia ixx="0.00030285" ixy="0.00000761" ixz="0.00000031" iyy="0.00022339" iyz="-0.00000001" izz="0.00039766" />-->
        </inertial>
    </link>
    
    <!-- Joint 5 -->
    <joint name="joint5" type="revolute">
        <parent link="link5"/>
        <child link="link6"/>
        <origin xyz="0.06300 0.04500 0.00000" rpy="0 0 0"/>
        <axis xyz="0 1 0"/>
        <limit velocity="6.5" effort="1000" lower="${-pi*0.5}" upper="${pi*0.5}" />
        <dynamics damping="0.7"/>
    </joint>
    
    <transmission name="tran5">
        <type>transmission_interface/SimpleTransmission</type>
        <joint name="joint5">
            <hardwareInterface>EffortJointInterface</hardwareInterface>
        </joint>
        <actuator name="motor5">
            <hardwareInterface>EffortJointInterface</hardwareInterface>
            <mechanicalReduction>1</mechanicalReduction>
        </actuator>
    </transmission>
    
    <!-- link 6 -->
    <link name="link6">
        <collision>
            <origin xyz="0 0 0" rpy="0 0 0"/>
            <geometry>
                <mesh filename="package://my_robotic_arm/meshes/link_6.stl" scale="0.001 0.001 0.001"/>
            </geometry>
        </collision>
        
        <visual>
            <origin xyz="0 0 0" rpy="0 0 0"/>
            <geometry>
                <mesh filename="package://my_robotic_arm/meshes/link_6.stl" scale="0.001 0.001 0.001"/>
            </geometry>
            <material name="grey"/>
        </visual>
        
        <inertial>
            <origin xyz="0.06831 -0.04457 0.00000" rpy="0 0 0"/>
            <!--<origin xyz="-0.05469 0.00043 0.00000" rpy="0 0 0"/>-->
            <mass value="0.43273"/>
            <inertia ixx="1.0" ixy="0.0" ixz="0.0" iyy="1.0" iyz="0.0" izz="1.0" />
            <!--<inertia ixx="0.00021512" ixy="0.00001009" ixz="0.00000000" iyy="0.00042827" iyz="0.00000000" izz="0.00051436" />-->
        </inertial>
    </link>
    
    <!-- Joint 6 -->
    <joint name="joint6" type="revolute">
        <parent link="link6"/>
        <child link="end_link"/>
        <origin xyz="0.12300 -0.04500 0.00000" rpy="${-pi} 0 0"/>
        <axis xyz="1 0 0"/>
        <limit velocity="6.5" effort="1000" lower="${-pi*0.5}" upper="${pi*0.5}" />
        <dynamics damping="0.7"/>
    </joint>
    
    <transmission name="tran6">
        <type>transmission_interface/SimpleTransmission</type>
        <joint name="joint6">
            <hardwareInterface>EffortJointInterface</hardwareInterface>
        </joint>
        <actuator name="motor6">
            <hardwareInterface>EffortJointInterface</hardwareInterface>
            <mechanicalReduction>1</mechanicalReduction>
        </actuator>
    </transmission>
    
    <!-- end link -->
    <link name="end_link">
        <collision>
            <origin xyz="0 0 0" rpy="0 0 0"/>
            <geometry>
                <mesh filename="package://my_robotic_arm/meshes/collision/SAKE_Palm_Dual.stl" scale="1 1 1"/>
            </geometry>
        </collision>
        
        <visual>
            <origin xyz="0 0 0" rpy="0 0 0"/>
            <geometry>
                <mesh filename="package://my_robotic_arm/meshes/visual/SAKE_Palm_Dual.stl" scale="1 1 1"/>
            </geometry>
            <material name="white">
                <color rgba="1 1 1 1"/>
            </material>
        </visual>
        
        <inertial>
            <origin xyz="0.0 0.00000 0.00000" rpy="0 0 0"/>
            <mass value="0.05"/>
            <inertia ixx="1.0" ixy="0.0" ixz="0.0" iyy="1.0" iyz="0.0" izz="1.0" />
            <!--<inertia ixx="0.00000938" ixy="0.0" ixz="0.0" iyy="0.00000338" iyz="0.0" izz="0.00000635" />-->
        </inertial> 
    </link>
    
    <!-- Joint l1 -->
    <joint name="joint_l1" type="revolute">
        <parent link="end_link"/>
        <child link="prox_l"/>
        <origin xyz="0.1055 -0.0300 0.00000" rpy="${pi*0.5} 0 0"/>
        <!--         <origin xyz="0.1200 -0.0400 0.00000" rpy="${-pi*0.5} 0 0"/> -->
        <axis xyz="0 1 0"/>                                                  <!--UPDATE AXIS HERE LATER-->
        <limit velocity="6.5" effort="1000" lower="${-pi*0.45}" upper="${pi*0.1}" />
        <dynamics damping="0.1"/>
    </joint>
    
    <!-- proximal left phalanx  -->
    <link name="prox_l">
        <collision>
            <origin xyz="0 0 0" rpy="0 0 0"/>
            <geometry>
                <mesh filename="package://my_robotic_arm/meshes/prox.stl" scale="1 1 1"/>
            </geometry>
        </collision>
        
        <visual>
            <origin xyz="0 0 0" rpy="0 0 0"/>
            <geometry>
                <mesh filename="package://my_robotic_arm/meshes/prox.stl" scale="1 1 1"/>
            </geometry>
            <material name="blue"/>
        </visual>
        
        <inertial>
            <origin xyz="0.0 0.00000 0.00000" rpy="0 0 0"/>
            <mass value="0.05"/>
            <inertia ixx="1.0" ixy="0.0" ixz="0.0" iyy="1.0" iyz="0.0" izz="1.0" />
        </inertial> 
    </link>
    
    <!-- Joint l2 -->
    <joint name="joint_l2" type="revolute">
        <parent link="prox_l"/>
        <child link="dist_l"/>
        <origin xyz="0.052 0.0000 0.00000" rpy="0 0 0"/>
        <!--         <origin xyz="0.1200 -0.0400 0.00000" rpy="${-pi*0.5} 0 0"/> -->
        <axis xyz="0 1 0"/>                                                 
        <limit velocity="6.5" effort="1000" lower="0" upper="${pi*0.65}" />
        <dynamics damping="0.1"/>
    </joint>
    
    <!-- distal left phalanx  -->
    <link name="dist_l">
        <collision>
            <origin xyz="0 0 0" rpy="0 0 0"/>
            <geometry>
                <mesh filename="package://my_robotic_arm/meshes/dist.stl" scale="1 1 1"/>
            </geometry>
        </collision>
        
        <visual>
            <origin xyz="0 0 0" rpy="0 0 0"/>
            <geometry>
                <mesh filename="package://my_robotic_arm/meshes/dist.stl" scale="1 1 1"/>
            </geometry>
            <material name="blue"/>
        </visual>
        
        <inertial>
            <origin xyz="0.0 0.00000 0.00000" rpy="0 0 0"/>
            <mass value="0.05"/>
            <inertia ixx="1.0" ixy="0.0" ixz="0.0" iyy="1.0" iyz="0.0" izz="1.0" />
        </inertial> 
    </link>
    
    <!-- Joint r1 -->
    <joint name="joint_r1" type="revolute">
        <parent link="end_link"/>
        <child link="prox_r"/>
        <origin xyz="0.1055 0.0300 0.00000" rpy="${-pi*0.5} 0 0"/>
        <!--         <origin xyz="0.1200 -0.0400 0.00000" rpy="${-pi*0.5} 0 0"/> -->
        <axis xyz="0 1 0"/>
        <limit velocity="6.5" effort="1000" lower="${-pi*0.45}" upper="${pi*0.1}" />
        <dynamics damping="0.9"/>
    </joint>
    
    <!-- proximal right phalanx  -->
    <link name="prox_r">
        <collision>
            <origin xyz="0 0 0" rpy="0 0 0"/>
            <geometry>
                <mesh filename="package://my_robotic_arm/meshes/prox.stl" scale="1 1 1"/>
            </geometry>
        </collision>
        
        <visual>
            <origin xyz="0 0 0" rpy="0 0 0"/>
            <geometry>
                <mesh filename="package://my_robotic_arm/meshes/prox.stl" scale="1 1 1"/>
            </geometry>
            <material name="blue"/>
        </visual>
        
        <inertial>
            <origin xyz="0.0 0.00000 0.00000" rpy="0 0 0"/>
            <mass value="0.05"/>
            <inertia ixx="1.0" ixy="0.0" ixz="0.0" iyy="1.0" iyz="0.0" izz="1.0" />
        </inertial> 
    </link>
    
    <!-- Joint r2 -->
    <joint name="joint_r2" type="revolute">
        <parent link="prox_r"/>
        <child link="dist_r"/>
        <origin xyz="0.052 0.0000 0.00000" rpy="0 0 0"/>
        <!--         <origin xyz="0.1200 -0.0400 0.00000" rpy="${-pi*0.5} 0 0"/> -->
        <axis xyz="0 1 0"/>                                                 
        <limit velocity="6.5" effort="1000" lower="0" upper="${pi*0.65}" />
        <dynamics damping="0.9"/>
    </joint>
    
    <!-- distal left phalanx  -->
    <link name="dist_r">
        <collision>
            <origin xyz="0 0 0" rpy="0 0 0"/>
            <geometry>
                <mesh filename="package://my_robotic_arm/meshes/dist.stl" scale="1 1 1"/>
            </geometry>
        </collision>
        
        <visual>
            <origin xyz="0 0 0" rpy="0 0 0"/>
            <geometry>
                <mesh filename="package://my_robotic_arm/meshes/dist.stl" scale="1 1 1"/>
            </geometry>
            <!--             <material name="blue"/> -->
        </visual>
        
        <inertial>
            <origin xyz="0.0 0.00000 0.00000" rpy="0 0 0"/>
            <mass value="0.05"/>
            <inertia ixx="1.0" ixy="0.0" ixz="0.0" iyy="1.0" iyz="0.0" izz="1.0" />
            
            <!--             <origin xyz="0.00337 0.00000 0.00000" rpy="0 0 0"/> -->
            <!--            <mass value="0.01919"/>
            <inertia ixx="1.0" ixy="0.0" ixz="0.0" iyy="1.0" iyz="0.0" izz="1.0" />-->
        </inertial> 
    </link>
    
    
    
    
    <!--     TRANSMISSIONS FOR THE GRIPPER -->
    <transmission name="joint_r1">
        <type>transmission_interface/SimpleTransmission</type>
        <joint name="joint_r1">
            <hardwareInterface>EffortJointInterface</hardwareInterface>
        </joint>
        <actuator name="motor_grip_r1">
            <hardwareInterface>EffortJointInterface</hardwareInterface>
            <mechanicalReduction>1</mechanicalReduction>
        </actuator>
    </transmission>
    
    <transmission name="joint_r2">
        <type>transmission_interface/SimpleTransmission</type>
        <joint name="joint_r2">
            <hardwareInterface>EffortJointInterface</hardwareInterface>
        </joint>
        <actuator name="motor_grip_r2">
            <hardwareInterface>EffortJointInterface</hardwareInterface>
            <mechanicalReduction>1</mechanicalReduction>
        </actuator>
    </transmission>
<!--    
    <gazebo>
        <plugin name="gazebo_ros_control" filename="libgazebo_ros_control.so">
            <robotNamespace>/robotis_manipulator_h</robotNamespace>
        </plugin>
    </gazebo>-->
    
</robot>
